ata: None
Response status: 200
Response text: [{"id":1,"chat_id":"263785494594","name":"Ngonidzashe","surname":"Zimbwa","date_of_birth":"03/10/2003","nerdx_id":"NEYHAI","referred_by_nerdx_id":null,"created_at":"2025-07-18T09:00:39.968177","updated_at":"2025-07-18T09:00:40.589828"}]
2025-08-23 16:51:59,155 - services.whatsapp_service - INFO - Message sent successfully to 263785494594
2025-08-23 16:51:59,157 - services.math_question_generator - INFO - AI API attempt 1/3 (timeout: 30s)
[2025-08-23 16:52:27 +0000] [2701] [CRITICAL] WORKER TIMEOUT (pid:2712)
[2025-08-23 16:52:27 +0000] [2712] [ERROR] Error handling request /webhook/whatsapp
Traceback (most recent call last):
  File "/home/runner/workspace/.pythonlibs/lib/python3.11/site-packages/gunicorn/workers/sync.py", line 134, in handle
    self.handle_request(listener, req, client, addr)
  File "/home/runner/workspace/.pythonlibs/lib/python3.11/site-packages/gunicorn/workers/sync.py", line 177, in handle_request
    respiter = self.wsgi(environ, resp.start_response)
               ^^^^^^^^^^^^^^^^^^^^^^^^^^^^^^^^^^^^^^^
  File "/home/runner/workspace/.pythonlibs/lib/python3.11/site-packages/flask/app.py", line 1536, in __call__
    return self.wsgi_app(environ, start_response)
           ^^^^^^^^^^^^^^^^^^^^^^^^^^^^^^^^^^^^^^
  File "/home/runner/workspace/.pythonlibs/lib/python3.11/site-packages/werkzeug/middleware/proxy_fix.py", line 183, in __call__
    return self.app(environ, start_response)
           ^^^^^^^^^^^^^^^^^^^^^^^^^^^^^^^^^
  File "/home/runner/workspace/.pythonlibs/lib/python3.11/site-packages/flask/app.py", line 1511, in wsgi_app
    response = self.full_dispatch_request()
               ^^^^^^^^^^^^^^^^^^^^^^^^^^^^
  File "/home/runner/workspace/.pythonlibs/lib/python3.11/site-packages/flask/app.py", line 917, in full_dispatch_request
    rv = self.dispatch_request()
         ^^^^^^^^^^^^^^^^^^^^^^^
  File "/home/runner/workspace/.pythonlibs/lib/python3.11/site-packages/flask/app.py", line 902, in dispatch_request
    return self.ensure_sync(self.view_functions[rule.endpoint])(**view_args)  # type: ignore[no-any-return]
           ^^^^^^^^^^^^^^^^^^^^^^^^^^^^^^^^^^^^^^^^^^^^^^^^^^^^^^^^^^^^^^^^^
  File "/home/runner/workspace/api/webhook.py", line 135, in handle_webhook
    handle_interactive_message(user_id, message['interactive'])
  File "/home/runner/workspace/api/webhook.py", line 652, in handle_interactive_message
    graph_practice_handler.handle_graph_generate(user_id, module_id)
  File "/home/runner/workspace/handlers/graph_practice_handler.py", line 258, in handle_graph_generate
    question_data = self.question_generator.generate_question(
                    ^^^^^^^^^^^^^^^^^^^^^^^^^^^^^^^^^^^^^^^^^^
  File "/home/runner/workspace/services/math_question_generator.py", line 41, in generate_question
    question_data = self._send_api_request(prompt)
                    ^^^^^^^^^^^^^^^^^^^^^^^^^^^^^^
  File "/home/runner/workspace/services/math_question_generator.py", line 200, in _send_api_request
    response = requests.post(
               ^^^^^^^^^^^^^^
  File "/home/runner/workspace/.pythonlibs/lib/python3.11/site-packages/requests/api.py", line 115, in post
    return request("post", url, data=data, json=json, **kwargs)
           ^^^^^^^^^^^^^^^^^^^^^^^^^^^^^^^^^^^^^^^^^^^^^^^^^^^^
  File "/home/runner/workspace/.pythonlibs/lib/python3.11/site-packages/requests/api.py", line 59, in request
    return session.request(method=method, url=url, **kwargs)
           ^^^^^^^^^^^^^^^^^^^^^^^^^^^^^^^^^^^^^^^^^^^^^^^^^
  File "/home/runner/workspace/.pythonlibs/lib/python3.11/site-packages/requests/sessions.py", line 589, in request
    resp = self.send(prep, **send_kwargs)
           ^^^^^^^^^^^^^^^^^^^^^^^^^^^^^^
  File "/home/runner/workspace/.pythonlibs/lib/python3.11/site-packages/requests/sessions.py", line 746, in send
    r.content
  File "/home/runner/workspace/.pythonlibs/lib/python3.11/site-packages/requests/models.py", line 902, in content
    self._content = b"".join(self.iter_content(CONTENT_CHUNK_SIZE)) or b""
                    ^^^^^^^^^^^^^^^^^^^^^^^^^^^^^^^^^^^^^^^^^^^^^^^
  File "/home/runner/workspace/.pythonlibs/lib/python3.11/site-packages/requests/models.py", line 820, in generate
    yield from self.raw.stream(chunk_size, decode_content=True)
  File "/home/runner/workspace/.pythonlibs/lib/python3.11/site-packages/urllib3/response.py", line 1088, in stream
    yield from self.read_chunked(amt, decode_content=decode_content)
  File "/home/runner/workspace/.pythonlibs/lib/python3.11/site-packages/urllib3/response.py", line 1248, in read_chunked
    self._update_chunk_length()
  File "/home/runner/workspace/.pythonlibs/lib/python3.11/site-packages/urllib3/response.py", line 1167, in _update_chunk_length
    line = self._fp.fp.readline()  # type: ignore[union-attr]
           ^^^^^^^^^^^^^^^^^^^^^^
  File "/nix/store/7d088dip86hlzri9sk0h78b63yfmx0a0-python3-3.11.13/lib/python3.11/socket.py", line 718, in readinto
    return self._sock.recv_into(b)
           ^^^^^^^^^^^^^^^^^^^^^^^
  File "/nix/store/7d088dip86hlzri9sk0h78b63yfmx0a0-python3-3.11.13/lib/python3.11/ssl.py", line 1314, in recv_into
    return self.read(nbytes, buffer)
           ^^^^^^^^^^^^^^^^^^^^^^^^^
  File "/nix/store/7d088dip86hlzri9sk0h78b63yfmx0a0-python3-3.11.13/lib/python3.11/ssl.py", line 1166, in read
    return self._sslobj.read(len, buffer)
           ^^^^^^^^^^^^^^^^^^^^^^^^^^^^^^
  File "/home/runner/workspace/.pythonlibs/lib/python3.11/site-packages/gunicorn/workers/base.py", line 204, in handle_abort
    sys.exit(1)
SystemExit: 1
[2025-08-23 16:52:27 +0000] [2712] [INFO] Worker exiting (pid: 2712)
[2025-08-23 16:52:27 +0000] [3027] [INFO] Booting worker with pid: 3027
[2025-08-23 16:52:28 +0000] [3027] [ERROR] Exception in worker process
Traceback (most recent call last):
  File "/home/runner/workspace/.pythonlibs/lib/python3.11/site-packages/sqlalchemy/engine/base.py", line 1967, in _exec_single_context
    self.dialect.do_execute(
  File "/home/runner/workspace/.pythonlibs/lib/python3.11/site-packages/sqlalchemy/engine/default.py", line 951, in do_execute
    cursor.execute(statement, parameters)
psycopg2.OperationalError: SSL connection has been closed unexpectedly


The above exception was the direct cause of the following exception:

Traceback (most recent call last):
  File "/home/runner/workspace/.pythonlibs/lib/python3.11/site-packages/gunicorn/arbiter.py", line 608, in spawn_worker
    worker.init_process()
  File "/home/runner/workspace/.pythonlibs/lib/python3.11/site-packages/gunicorn/workers/base.py", line 135, in init_process
    self.load_wsgi()
  File "/home/runner/workspace/.pythonlibs/lib/python3.11/site-packages/gunicorn/workers/base.py", line 147, in load_wsgi
    self.wsgi = self.app.wsgi()
                ^^^^^^^^^^^^^^^
  File "/home/runner/workspace/.pythonlibs/lib/python3.11/site-packages/gunicorn/app/base.py", line 66, in wsgi
    self.callable = self.load()
                    ^^^^^^^^^^^
  File "/home/runner/workspace/.pythonlibs/lib/python3.11/site-packages/gunicorn/app/wsgiapp.py", line 57, in load
    return self.load_wsgiapp()
           ^^^^^^^^^^^^^^^^^^^
  File "/home/runner/workspace/.pythonlibs/lib/python3.11/site-packages/gunicorn/app/wsgiapp.py", line 47, in load_wsgiapp
    return util.import_app(self.app_uri)
           ^^^^^^^^^^^^^^^^^^^^^^^^^^^^^
  File "/home/runner/workspace/.pythonlibs/lib/python3.11/site-packages/gunicorn/util.py", line 370, in import_app
    mod = importlib.import_module(module)
          ^^^^^^^^^^^^^^^^^^^^^^^^^^^^^^^
  File "/nix/store/7d088dip86hlzri9sk0h78b63yfmx0a0-python3-3.11.13/lib/python3.11/importlib/__init__.py", line 126, in import_module
    return _bootstrap._gcd_import(name[level:], package, level)
           ^^^^^^^^^^^^^^^^^^^^^^^^^^^^^^^^^^^^^^^^^^^^^^^^^^^^
  File "<frozen importlib._bootstrap>", line 1204, in _gcd_import
  File "<frozen importlib._bootstrap>", line 1176, in _find_and_load
  File "<frozen importlib._bootstrap>", line 1147, in _find_and_load_unlocked
  File "<frozen importlib._bootstrap>", line 690, in _load_unlocked
  File "<frozen importlib._bootstrap_external>", line 940, in exec_module
  File "<frozen importlib._bootstrap>", line 241, in _call_with_frames_removed
  File "/home/runner/workspace/main.py", line 1, in <module>
    from app import app
  File "/home/runner/workspace/app.py", line 45, in <module>
    db.create_all()
  File "/home/runner/workspace/.pythonlibs/lib/python3.11/site-packages/flask_sqlalchemy/extension.py", line 900, in create_all
    self._call_for_binds(bind_key, "create_all")
  File "/home/runner/workspace/.pythonlibs/lib/python3.11/site-packages/flask_sqlalchemy/extension.py", line 881, in _call_for_binds
    getattr(metadata, op_name)(bind=engine)
  File "/home/runner/workspace/.pythonlibs/lib/python3.11/site-packages/sqlalchemy/sql/schema.py", line 5924, in create_all
    bind._run_ddl_visitor(
  File "/home/runner/workspace/.pythonlibs/lib/python3.11/site-packages/sqlalchemy/engine/base.py", line 3252, in _run_ddl_visitor
    conn._run_ddl_visitor(visitorcallable, element, **kwargs)
  File "/home/runner/workspace/.pythonlibs/lib/python3.11/site-packages/sqlalchemy/engine/base.py", line 2459, in _run_ddl_visitor
    ).traverse_single(element)
      ^^^^^^^^^^^^^^^^^^^^^^^^
  File "/home/runner/workspace/.pythonlibs/lib/python3.11/site-packages/sqlalchemy/sql/visitors.py", line 661, in traverse_single
    return meth(obj, **kw)
           ^^^^^^^^^^^^^^^
  File "/home/runner/workspace/.pythonlibs/lib/python3.11/site-packages/sqlalchemy/sql/ddl.py", line 963, in visit_metadata
    [t for t in tables if self._can_create_table(t)]
  File "/home/runner/workspace/.pythonlibs/lib/python3.11/site-packages/sqlalchemy/sql/ddl.py", line 963, in <listcomp>
    [t for t in tables if self._can_create_table(t)]
                          ^^^^^^^^^^^^^^^^^^^^^^^^^
  File "/home/runner/workspace/.pythonlibs/lib/python3.11/site-packages/sqlalchemy/sql/ddl.py", line 928, in _can_create_table
    return not self.checkfirst or not self.dialect.has_table(
                                      ^^^^^^^^^^^^^^^^^^^^^^^
  File "<string>", line 2, in has_table
  File "/home/runner/workspace/.pythonlibs/lib/python3.11/site-packages/sqlalchemy/engine/reflection.py", line 89, in cache
    return fn(self, con, *args, **kw)
           ^^^^^^^^^^^^^^^^^^^^^^^^^^
  File "/home/runner/workspace/.pythonlibs/lib/python3.11/site-packages/sqlalchemy/dialects/postgresql/base.py", line 3494, in has_table
    return bool(connection.scalar(query, {"table_name": table_name}))
                ^^^^^^^^^^^^^^^^^^^^^^^^^^^^^^^^^^^^^^^^^^^^^^^^^^^^
  File "/home/runner/workspace/.pythonlibs/lib/python3.11/site-packages/sqlalchemy/engine/base.py", line 1308, in scalar
    return meth(
           ^^^^^
  File "/home/runner/workspace/.pythonlibs/lib/python3.11/site-packages/sqlalchemy/sql/elements.py", line 544, in _execute_on_scalar
    return self._execute_on_connection(
           ^^^^^^^^^^^^^^^^^^^^^^^^^^^^
  File "/home/runner/workspace/.pythonlibs/lib/python3.11/site-packages/sqlalchemy/sql/elements.py", line 526, in _execute_on_connection
    return connection._execute_clauseelement(
           ^^^^^^^^^^^^^^^^^^^^^^^^^^^^^^^^^^
  File "/home/runner/workspace/.pythonlibs/lib/python3.11/site-packages/sqlalchemy/engine/base.py", line 1641, in _execute_clauseelement
    ret = self._execute_context(
          ^^^^^^^^^^^^^^^^^^^^^^
  File "/home/runner/workspace/.pythonlibs/lib/python3.11/site-packages/sqlalchemy/engine/base.py", line 1846, in _execute_context
    return self._exec_single_context(
           ^^^^^^^^^^^^^^^^^^^^^^^^^^
  File "/home/runner/workspace/.pythonlibs/lib/python3.11/site-packages/sqlalchemy/engine/base.py", line 1986, in _exec_single_context
    self._handle_dbapi_exception(
  File "/home/runner/workspace/.pythonlibs/lib/python3.11/site-packages/sqlalchemy/engine/base.py", line 2355, in _handle_dbapi_exception
    raise sqlalchemy_exception.with_traceback(exc_info[2]) from e
  File "/home/runner/workspace/.pythonlibs/lib/python3.11/site-packages/sqlalchemy/engine/base.py", line 1967, in _exec_single_context
    self.dialect.do_execute(
  File "/home/runner/workspace/.pythonlibs/lib/python3.11/site-packages/sqlalchemy/engine/default.py", line 951, in do_execute
    cursor.execute(statement, parameters)
sqlalchemy.exc.OperationalError: (psycopg2.OperationalError) SSL connection has been closed unexpectedly

[SQL: SELECT pg_catalog.pg_class.relname 
FROM pg_catalog.pg_class JOIN pg_catalog.pg_namespace ON pg_catalog.pg_namespace.oid = pg_catalog.pg_class.relnamespace 
WHERE pg_catalog.pg_class.relname = %(table_name)s AND pg_catalog.pg_class.relkind = ANY (ARRAY[%(param_1)s, %(param_2)s, %(param_3)s, %(param_4)s, %(param_5)s]) AND pg_catalog.pg_table_is_visible(pg_catalog.pg_class.oid) AND pg_catalog.pg_namespace.nspname != %(nspname_1)s]
[parameters: {'table_name': 'questions', 'param_1': 'r', 'param_2': 'p', 'param_3': 'f', 'param_4': 'v', 'param_5': 'm', 'nspname_1': 'pg_catalog'}]
(Background on this error at: https://sqlalche.me/e/20/e3q8)
[2025-08-23 16:52:28 +0000] [3027] [INFO] Worker exiting (pid: 3027)
[2025-08-23 16:52:28 +0000] [2701] [ERROR] Worker (pid:3027) exited with code 3
[2025-08-23 16:52:28 +0000] [2701] [ERROR] Shutting down: Master
[2025-08-23 16:52:28 +0000] [2701] [ERROR] Reason: Worker failed to boot.
